Workbook

Sheet 01 Executive Summary
A1: CostProof — finance model
A2: The output of a causal cost-measurement engine, delivered as an FP&A workbook.
A3: SIMULATED DATA. The estate is synthetic (FOCUS 1.2, 400 resources, 540 days). Figures illustrate the method; ground truth exists only because the data is simulated.
A5: The problem
A6: Every cloud cost tool reports what was spent. None can prove what an optimisation saved,
A7: because teams act on spikes and spikes revert on their own. Before/after comparison
A8: credits the team for gravity. This workbook shows what changes when the saving is
A9: measured against a control group instead.
A11: Two workbooks, two questions
A12: costproof-business-case.xlsx asks: should an organisation buy the measurement layer?
A13: Its NPV counts only decision quality -- effort not wasted on fixes that did nothing.
A14: This workbook asks: what did the optimisation programme itself deliver, measured
... A19: Headline figures (formulas; active scenario)
A20: Measure | B20: Value | C20: Where it comes from
A21: Events measured | B21: ='04 Savings Attribution'!$D$127 -> 117 | C21: Savings Attribution
A22: Passing the parallel-trends check | B22: ='04 Savings Attribution'!$D$128 -> 103 | C22: Savings Attribution
A23: Before/after would report, per year | B23: ='04 Savings Attribution'!$D$131 -> 1693741 | C23: Savings Attribution — the industry's number
A24: Credited savings, per year | B24: ='04 Savings Attribution'!$D$133 -> 1872634 | C24: Savings Attribution — identified, gated
A25: Difference the method makes | B25: ='07 ROI Analysis'!$B$38 -> 178893.04 | C25: ROI Analysis
A26: Programme NPV, five years | B26: ='07 ROI Analysis'!$B$26 -> 2833109.4 | C26: ROI Analysis
A27: Benefit-to-cost ratio | B27: ='07 ROI Analysis'!$B$29 -> 2.8634267 | C27: ROI Analysis
A28: Payback, months | B28: ='07 ROI Analysis'!$B$32 -> 6.54707 | C28: ROI Analysis
A29: Budget variance over the period | B29: ='05 Budget vs Actual'!$Z$18 -> 0.071979076 | C29: Budget vs Actual
A30: SIMULATED: gross misattribution in before/after | B30: ='04 Savings Attribution'!$D$135 -> 450967.84 | C30: Savings Attribution — needs ground truth
A31: Active scenario / attribution policy | B31: ='10 Assumptions'!$B$27&" / "&IF('10 Assumptions'!$B$24="Yes","all","PT gate") -> Base / PT gate | C31: Assumptions
A33: How to read this workbook
A34: Blue cells are inputs; black cells are formulas; green cells link to another sheet.
A35: Only estimates that pass the parallel-trends check are credited, unless you flip the
A36: policy switch on Assumptions. Bear/Bull/Base are execution scenarios, not measurement
A37: scenarios: the estimator's own error is quantified on Savings Attribution.
A38: Peach cells use simulated ground truth. They are the reason the method can be
A39: validated here and the reason it would be needed on real data, where they do not exist.
A41: Sheets
A42: 02 Raw Cost Data | C42: monthly cost by business unit; the pivot is formulas
A43: 03 Optimization Events | C43: the intervention register
A44: 04 Savings Attribution | C44: per-event estimates, the gate, the credited total
A45: 05 Budget vs Actual | C45: run-rate budget vs actual, by unit and month
A46: 06 Forecast | C46: twelve months forward, two methods
A47: 07 ROI Analysis | C47: programme cash flows, NPV, ROI, IRR, payback
A48: 08 Scenario Analysis | C48: Base / Bull / Bear side by side
...

Sheet 02 Raw Cost Data
A1: Raw cost data
A2: Monthly effective, billed and list cost by business unit, from the silver layer (Usage rows, complete months only). The pivot on the right is formulas.
A3: SIMULATED DATA. The estate is synthetic (FOCUS 1.2, 400 resources, 540 days). Figures illustrate the method; ground truth exists only because the data is simulated.
G4: Effective cost by month and business unit (SUMIFS over the table)
A5: Month | B5: Business unit | C5: Effective cost | D5: Billed cost | E5: List cost | G5: Month | H5: # | I5: bu-assist | J5: bu-checkout | K5: bu-datalake | L5: bu-datasci | M5: bu-platform | N5: bu-search | O5: unallocated | P5: Total
A6: 45658 | B6: bu-assist | C6: 141869.63 | D6: 116240.39 | E6: 158448.04 | G6: 45658 | H6: 1 | I6: =SUMIFS($C$6:$C$124,$A$6:$A$124,$G6,$B$6:$B$124,I$5) -> 141869.63 | J6: =SUMIFS($C$6:$C$124,$A$6:$A$124,$G6,$B$6:$B$124,J$5) -> 77461.639 | K6: =SUMIFS($C$6:$C$124,$A$6:$A$124,$G6,$B$6:$B$124,K$5) -> 57576.421 | L6: =SUMIFS($C$6:$C$124,$A$6:$A$124,$G6,$B$6:$B$124,L$5) -> 114791.87 | M6: =SUMIFS($C$6:$C$124,$A$6:$A$124,$G6,$B$6:$B$124,M$5) -> 70348.918 | N6: =SUMIFS($C$6:$C$124,$A$6:$A$124,$G6,$B$6:$B$124,N$5) -> 80411.691 | O6: =SUMIFS($C$6:$C$124,$A$6:$A$124,$G6,$B$6:$B$124,O$5) -> 69283.921 | P6: =SUM(I6:O6) -> 611744.09
A7: 45658 | B7: bu-checkout | C7: 77461.639 | D7: 45232.614 | E7: 93014.008 | G7: 45689 | H7: 2 | I7: =SUMIFS($C$6:$C$124,$A$6:$A$124,$G7,$B$6:$B$124,I$5) -> 131285.97 | J7: =SUMIFS($C$6:$C$124,$A$6:$A$124,$G7,$B$6:$B$124,J$5) -> 71395.969 | K7: =SUMIFS($C$6:$C$124,$A$6:$A$124,$G7,$B$6:$B$124,K$5) -> 55351.038 | L7: =SUMIFS($C$6:$C$124,$A$6:$A$124,$G7,$B$6:$B$124,L$5) -> 129367.1 | M7: =SUMIFS($C$6:$C$124,$A$6:$A$124,$G7,$B$6:$B$124,M$5) -> 68187.358 | N7: =SUMIFS($C$6:$C$124,$A$6:$A$124,$G7,$B$6:$B$124,N$5) -> 75021.547 | O7: =SUMIFS($C$6:$C$124,$A$6:$A$124,$G7,$B$6:$B$124,O$5) -> 64715.596 | P7: =SUM(I7:O7) -> 595324.58
A8: 45658 | B8: bu-datalake | C8: 57576.421 | D8: 47000.025 | E8: 64010.931 | G8: 45717 | H8: 3 | I8: =SUMIFS($C$6:$C$124,$A$6:$A$124,$G8,$B$6:$B$124,I$5) -> 170694.11 | J8: =SUMIFS($C$6:$C$124,$A$6:$A$124,$G8,$B$6:$B$124,J$5) -> 87880.492 | K8: =SUMIFS($C$6:$C$124,$A$6:$A$124,$G8,$B$6:$B$124,K$5) -> 61084.426 | L8: =SUMIFS($C$6:$C$124,$A$6:$A$124,$G8,$B$6:$B$124,L$5) -> 199666.2 | M8: =SUMIFS($C$6:$C$124,$A$6:$A$124,$G8,$B$6:$B$124,M$5) -> 69367.665 | N8: =SUMIFS($C$6:$C$124,$A$6:$A$124,$G8,$B$6:$B$124,N$5) -> 87877.055 | O8: =SUMIFS($C$6:$C$124,$A$6:$A$124,$G8,$B$6:$B$124,O$5) -> 75572.938 | P8: =SUM(I8:O8) -> 752142.89
A9: 45658 | B9: bu-datasci | C9: 114791.87 | D9: 112932.93 | E9: 118048.31 | G9: 45748 | H9: 4 | I9: =SUMIFS($C$6:$C$124,$A$6:$A$124,$G9,$B$6:$B$124,I$5) -> 173641.2 | J9: =SUMIFS($C$6:$C$124,$A$6:$A$124,$G9,$B$6:$B$124,J$5) -> 91758.287 | K9: =SUMIFS($C$6:$C$124,$A$6:$A$124,$G9,$B$6:$B$124,K$5) -> 68648.745 | L9: =SUMIFS($C$6:$C$124,$A$6:$A$124,$G9,$B$6:$B$124,L$5) -> 155580.08 | M9: =SUMIFS($C$6:$C$124,$A$6:$A$124,$G9,$B$6:$B$124,M$5) -> 72773.121 | N9: =SUMIFS($C$6:$C$124,$A$6:$A$124,$G9,$B$6:$B$124,N$5) -> 89750.976 | O9: =SUMIFS($C$6:$C$124,$A$6:$A$124,$G9,$B$6:$B$124,O$5) -> 73834.677 | P9: =SUM(I9:O9) -> 725987.08
A10: 45658 | B10: bu-platform | C10: 70348.918 | D10: 59598.308 | E10: 77787.228 | G10: 45778 | H10: 5 | I10: =SUMIFS($C$6:$C$124,$A$6:$A$124,$G10,$B$6:$B$124,I$5) -> 168584.86 | J10: =SUMIFS($C$6:$C$124,$A$6:$A$124,$G10,$B$6:$B$124,J$5) -> 96378.562 | K10: =SUMIFS($C$6:$C$124,$A$6:$A$124,$G10,$B$6:$B$124,K$5) -> 70552.176 | L10: =SUMIFS($C$6:$C$124,$A$6:$A$124,$G10,$B$6:$B$124,L$5) -> 161497.27 | M10: =SUMIFS($C$6:$C$124,$A$6:$A$124,$G10,$B$6:$B$124,M$5) -> 72013.672 | N10: =SUMIFS($C$6:$C$124,$A$6:$A$124,$G10,$B$6:$B$124,N$5) -> 94285.115 | O10: =SUMIFS($C$6:$C$124,$A$6:$A$124,$G10,$B$6:$B$124,O$5) -> 84541.533 | P10: =SUM(I10:O10) -> 747853.19
A11: 45658 | B11: bu-search | C11: 80411.691 | D11: 63621.62 | E11: 91372.071 | G11: 45809 | H11: 6 | I11: =SUMIFS($C$6:$C$124,$A$6:$A$124,$G11,$B$6:$B$124,I$5) -> 157180.44 | J11: =SUMIFS($C$6:$C$124,$A$6:$A$124,$G11,$B$6:$B$124,J$5) -> 92478.419 | K11: =SUMIFS($C$6:$C$124,$A$6:$A$124,$G11,$B$6:$B$124,K$5) -> 70541.829 | L11: =SUMIFS($C$6:$C$124,$A$6:$A$124,$G11,$B$6:$B$124,L$5) -> 140313.55 | M11: =SUMIFS($C$6:$C$124,$A$6:$A$124,$G11,$B$6:$B$124,M$5) -> 73722.175 | N11: =SUMIFS($C$6:$C$124,$A$6:$A$124,$G11,$B$6:$B$124,N$5) -> 90268.734 | O11: =SUMIFS($C$6:$C$124,$A$6:$A$124,$G11,$B$6:$B$124,O$5) -> 77440.757 | P11: =SUM(I11:O11) -> 701945.9
A12: 45658 | B12: unallocated | C12: 69283.921 | D12: 50164.525 | E12: 79175.308 | G12: 45839 | H12: 7 | I12: =SUMIFS($C$6:$C$124,$A$6:$A$124,$G12,$B$6:$B$124,I$5) -> 157484.7 | J12: =SUMIFS($C$6:$C$124,$A$6:$A$124,$G12,$B$6:$B$124,J$5) -> 93742.453 | K12: =SUMIFS($C$6:$C$124,$A$6:$A$124,$G12,$B$6:$B$124,K$5) -> 71220.469 | L12: =SUMIFS($C$6:$C$124,$A$6:$A$124,$G12,$B$6:$B$124,L$5) -> 154568.58 | M12: =SUMIFS($C$6:$C$124,$A$6:$A$124,$G12,$B$6:$B$124,M$5) -> 70392.849 | N12: =SUMIFS($C$6:$C$124,$A$6:$A$124,$G12,$B$6:$B$124,N$5) -> 97421.955 | O12: =SUMIFS($C$6:$C$124,$A$6:$A$124,$G12,$B$6:$B$124,O$5) -> 78358.728 | P12: =SUM(I12:O12) -> 723189.72
A13: 45689 | B13: bu-assist | C13: 131285.97 | D13: 108775.44 | E13: 145911.61 | G13: 45870 | H13: 8 | I13: =SUMIFS($C$6:$C$124,$A$6:$A$124,$G13,$B$6:$B$124,I$5) -> 164579.11 | J13: =SUMIFS($C$6:$C$124,$A$6:$A$124,$G13,$B$6:$B$124,J$5) -> 97362.162 | K13: =SUMIFS($C$6:$C$124,$A$6:$A$124,$G13,$B$6:$B$124,K$5) -> 63816.123 | L13: =SUMIFS($C$6:$C$124,$A$6:$A$124,$G13,$B$6:$B$124,L$5) -> 143516.31 | M13: =SUMIFS($C$6:$C$124,$A$6:$A$124,$G13,$B$6:$B$124,M$5) -> 73737.598 | N13: =SUMIFS($C$6:$C$124,$A$6:$A$124,$G13,$B$6:$B$124,N$5) -> 100098.44 | O13: =SUMIFS($C$6:$C$124,$A$6:$A$124,$G13,$B$6:$B$124,O$5) -> 77229.281 | P13: =SUM(I13:O13) -> 720339.02
A14: 45689 | B14: bu-checkout | C14: 71395.969 | D14: 40575.811 | E14: 85967.485 | G14: 45901 | H14: 9 | I14: =SUMIFS($C$6:$C$124,$A$6:$A$124,$G14,$B$6:$B$124,I$5) -> 158979.41 | J14: =SUMIFS($C$6:$C$124,$A$6:$A$124,$G14,$B$6:$B$124,J$5) -> 92261.506 | K14: =SUMIFS($C$6:$C$124,$A$6:$A$124,$G14,$B$6:$B$124,K$5) -> 61211.517 | L14: =SUMIFS($C$6:$C$124,$A$6:$A$124,$G14,$B$6:$B$124,L$5) -> 159667.6 | M14: =SUMIFS($C$6:$C$124,$A$6:$A$124,$G14,$B$6:$B$124,M$5) -> 77160.957 | N14: =SUMIFS($C$6:$C$124,$A$6:$A$124,$G14,$B$6:$B$124,N$5) -> 95928.862 | O14: =SUMIFS($C$6:$C$124,$A$6:$A$124,$G14,$B$6:$B$124,O$5) -> 81095.158 | P14: =SUM(I14:O14) -> 726305.01
A15: 45689 | B15: bu-datalake | C15: 55351.038 | D15: 45654.664 | E15: 61360.855 | G15: 45931 | H15: 10 | I15: =SUMIFS($C$6:$C$124,$A$6:$A$124,$G15,$B$6:$B$124,I$5) -> 173558.54 | J15: =SUMIFS($C$6:$C$124,$A$6:$A$124,$G15,$B$6:$B$124,J$5) -> 111068.97 | K15: =SUMIFS($C$6:$C$124,$A$6:$A$124,$G15,$B$6:$B$124,K$5) -> 61411.786 | L15: =SUMIFS($C$6:$C$124,$A$6:$A$124,$G15,$B$6:$B$124,L$5) -> 164202.51 | M15: =SUMIFS($C$6:$C$124,$A$6:$A$124,$G15,$B$6:$B$124,M$5) -> 87267.349 | N15: =SUMIFS($C$6:$C$124,$A$6:$A$124,$G15,$B$6:$B$124,N$5) -> 109009.59 | O15: =SUMIFS($C$6:$C$124,$A$6:$A$124,$G15,$B$6:$B$124,O$5) -> 85190.819 | P15: =SUM(I15:O15) -> 791709.56
A16: 45689 | B16: bu-datasci | C16: 129367.1 | D16: 127972.22 | E16: 132211.37 | G16: 45962 | H16: 11 | I16: =SUMIFS($C$6:$C$124,$A$6:$A$124,$G16,$B$6:$B$124,I$5) -> 170043.12 | J16: =SUMIFS($C$6:$C$124,$A$6:$A$124,$G16,$B$6:$B$124,J$5) -> 132965.8 | K16: =SUMIFS($C$6:$C$124,$A$6:$A$124,$G16,$B$6:$B$124,K$5) -> 58841.39 | L16: =SUMIFS($C$6:$C$124,$A$6:$A$124,$G16,$B$6:$B$124,L$5) -> 144469.26 | M16: =SUMIFS($C$6:$C$124,$A$6:$A$124,$G16,$B$6:$B$124,M$5) -> 85378.466 | N16: =SUMIFS($C$6:$C$124,$A$6:$A$124,$G16,$B$6:$B$124,N$5) -> 119213.62 | O16: =SUMIFS($C$6:$C$124,$A$6:$A$124,$G16,$B$6:$B$124,O$5) -> 90806.45 | P16: =SUM(I16:O16) -> 801718.11
A17: 45689 | B17: bu-platform | C17: 68187.358 | D17: 57902.004 | E17: 75400.181 | G17: 45992 | H17: 12 | I17: =SUMIFS($C$6:$C$124,$A$6:$A$124,$G17,$B$6:$B$124,I$5) -> 196719.21 | J17: =SUMIFS($C$6:$C$124,$A$6:$A$124,$G17,$B$6:$B$124,J$5) -> 126834.23 | K17: =SUMIFS($C$6:$C$124,$A$6:$A$124,$G17,$B$6:$B$124,K$5) -> 67374.564 | L17: =SUMIFS($C$6:$C$124,$A$6:$A$124,$G17,$B$6:$B$124,L$5) -> 179764.62 | M17: =SUMIFS($C$6:$C$124,$A$6:$A$124,$G17,$B$6:$B$124,M$5) -> 77821.171 | N17: =SUMIFS($C$6:$C$124,$A$6:$A$124,$G17,$B$6:$B$124,N$5) -> 113922.09 | O17: =SUMIFS($C$6:$C$124,$A$6:$A$124,$G17,$B$6:$B$124,O$5) -> 93942.017 | P17: =SUM(I17:O17) -> 856377.91
... A22: 45717 | B22: bu-datalake | C22: 61084.426 | D22: 49295.274 | E22: 68135.704 | G22: 46143 | H22: 17 | I22: =SUMIFS($C$6:$C$124,$A$6:$A$124,$G22,$B$6:$B$124,I$5) -> 199289.57 | J22: =SUMIFS($C$6:$C$124,$A$6:$A$124,$G22,$B$6:$B$124,J$5) -> 107902.82 | K22: =SUMIFS($C$6:$C$124,$A$6:$A$124,$G22,$B$6:$B$124,K$5) -> 79901.899 | L22: =SUMIFS($C$6:$C$124,$A$6:$A$124,$G22,$B$6:$B$124,L$5) -> 182830.56 | M22: =SUMIFS($C$6:$C$124,$A$6:$A$124,$G22,$B$6:$B$124,M$5) -> 77319.347 | N22: =SUMIFS($C$6:$C$124,$A$6:$A$124,$G22,$B$6:$B$124,N$5) -> 102550.65 | O22: =SUMIFS($C$6:$C$124,$A$6:$A$124,$G22,$B$6:$B$124,O$5) -> 87225.165 | P22: =SUM(I22:O22) -> 837020.01
A23: 45717 | B23: bu-datasci | C23: 199666.2 | D23: 197792.74 | E23: 203002.03 | G23: Total | I23: =SUM(I6:I22) -> 2957101.1 | J23: =SUM(J6:J22) -> 1682818.3 | K23: =SUM(K6:K22) -> 1133940.4 | L23: =SUM(L6:L22) -> 2815330.8 | M23: =SUM(M6:M22) -> 1268389.3 | N23: =SUM(N6:N22) -> 1630794.6 | O23: =SUM(O6:O22) -> 1367224.9 | P23: =SUM(P6:P22) -> 12855600
A24: 45717 | B24: bu-platform | C24: 69367.665 | D24: 56372.595 | E24: 77787.487
A25: 45717 | B25: bu-search | C25: 87877.055 | D25: 69395.702 | E25: 99862.84 | G25: Effective cost is used throughout: it amortises commitments across the period they cover. Billed cost would show prepaid resources as free.
A26: 45717 | B26: unallocated | C26: 75572.938 | D26: 57307.597 | E26: 85723.992
A27: 45748 | B27: bu-assist | C27: 173641.2 | D27: 147917.62 | E27: 190473.95
A28: 45748 | B28: bu-checkout | C28: 91758.287 | D28: 51592.344 | E28: 110942.46
A29: 45748 | B29: bu-datalake | C29: 68648.745 | D29: 54663.854 | E29: 76776.671
A30: 45748 | B30: bu-datasci | C30: 155580.08 | D30: 153718.36 | E30: 158961.84
A31: 45748 | B31: bu-platform | C31: 72773.121 | D31: 60406.694 | E31: 81046.82
A32: 45748 | B32: bu-search | C32: 89750.976 | D32: 69717.822 | E32: 102308.97
A33: 45748 | B33: unallocated | C33: 73834.677 | D33: 56369.364 | E33: 83769.131
A34: 45778 | B34: bu-assist | C34: 168584.86 | D34: 143013.4 | E34: 185353.09
A35: 45778 | B35: bu-checkout | C35: 96378.562 | D35: 54302.444 | E35: 116714.19
A36: 45778 | B36: bu-datalake | C36: 70552.176 | D36: 55686.552 | E36: 79130.746
A37: 45778 | B37: bu-datasci | C37: 161497.27 | D37: 159412.58 | E37: 165662.2
... A124: 46143 | B124: unallocated | C124: 87225.165 | D124: 71175.996 | E124: 98652.246

Sheet 03 Optimization Events
A1: Optimisation events
A2: Every intervention the study measured: what was done, to which resource, when, and what it was costing beforehand. The register the attribution sheet reads.
A3: SIMULATED DATA. The estate is synthetic (FOCUS 1.2, 400 resources, 540 days). Figures illustrate the method; ground truth exists only because the data is simulated.
L4: Events by action
A5: Event | B5: Resource | C5: Business unit | D5: Action | E5: Action date | F5: Trigger z | G5: Donors | H5: Pre-period daily run-rate | I5: Annualised run-rate | L5: Action | M5: Count | N5: Annualised run-rate
A6: i-114 | B6: r-0026 | C6: bu-search | D6: delete_orphaned_volume | E6: 45779 | F6: 2.3954552 | G6: 40 | H6: 125.34635 | I6: =H6*365 -> 45751.417 | L6: cache_inference_results | M6: =COUNTIF($D$6:$D$122,L6) -> 20 | N6: =SUMIF($D$6:$D$122,L6,$I$6:$I$122) -> 724939.68
A7: i-028 | B7: r-0059 | C7: bu-datasci | D7: delete_orphaned_volume | E7: 45793 | F7: 0.71197622 | G7: 40 | H7: 20.056545 | I7: =H7*365 -> 7320.639 | L7: consolidate_cluster | M7: =COUNTIF($D$6:$D$122,L7) -> 14 | N7: =SUMIF($D$6:$D$122,L7,$I$6:$I$122) -> 408333.09
A8: i-088 | B8: r-0260 | C8: bu-platform | D8: cache_inference_results | E8: 45793 | F8: 2.7694056 | G8: 40 | H8: 8.8429833 | I8: =H8*365 -> 3227.6889 | L8: delete_orphaned_volume | M8: =COUNTIF($D$6:$D$122,L8) -> 17 | N8: =SUMIF($D$6:$D$122,L8,$I$6:$I$122) -> 514985.12
A9: i-027 | B9: r-0374 | C9: bu-platform | D9: cache_inference_results | E9: 45793 | F9: 0.72023353 | G9: 40 | H9: 47.16402 | I9: =H9*365 -> 17214.867 | L9: enable_autoscaling | M9: =COUNTIF($D$6:$D$122,L9) -> 13 | N9: =SUMIF($D$6:$D$122,L9,$I$6:$I$122) -> 497301.63
A10: i-030 | B10: r-0097 | C10: bu-checkout | D10: enable_autoscaling | E10: 45797 | F10: 0.70693398 | G10: 40 | H10: 66.663108 | I10: =H10*365 -> 24332.034 | L10: migrate_storage_class | M10: =COUNTIF($D$6:$D$122,L10) -> 17 | N10: =SUMIF($D$6:$D$122,L10,$I$6:$I$122) -> 831654.43
A11: i-049 | B11: r-0372 | C11: bu-checkout | D11: cache_inference_results | E11: 45801 | F11: 0.63210692 | G11: 40 | H11: 182.71683 | I11: =H11*365 -> 66691.642 | L11: rightsize_instance | M11: =COUNTIF($D$6:$D$122,L11) -> 14 | N11: =SUMIF($D$6:$D$122,L11,$I$6:$I$122) -> 409554.87
A12: i-029 | B12: r-0164 | C12: bu-platform | D12: tune_batch_size | E12: 45801 | F12: 0.71166163 | G12: 40 | H12: 24.751056 | I12: =H12*365 -> 9034.1356 | L12: schedule_shutdown | M12: =COUNTIF($D$6:$D$122,L12) -> 12 | N12: =SUMIF($D$6:$D$122,L12,$I$6:$I$122) -> 403691.31
A13: i-011 | B13: r-0352 | C13: bu-datalake | D13: consolidate_cluster | E13: 45805 | F13: 0.89201822 | G13: 40 | H13: 64.279136 | I13: =H13*365 -> 23461.885 | L13: tune_batch_size | M13: =COUNTIF($D$6:$D$122,L13) -> 10 | N13: =SUMIF($D$6:$D$122,L13,$I$6:$I$122) -> 334141.69
A14: i-014 | B14: r-0227 | C14: bu-assist | D14: migrate_storage_class | E14: 45808 | F14: 0.88304188 | G14: 40 | H14: 445.07706 | I14: =H14*365 -> 162453.13 | L14: Total | M14: =SUM(M6:M13) -> 117 | N14: =SUM(N6:N13) -> 4124601.8
A15: i-042 | B15: r-0295 | C15: bu-search | D15: enable_autoscaling | E15: 45815 | F15: 0.65998359 | G15: 40 | H15: 47.877922 | I15: =H15*365 -> 17475.441
A16: i-067 | B16: r-0307 | C16: bu-assist | D16: consolidate_cluster | E16: 45822 | F16: 0.44301192 | G16: 40 | H16: 23.312213 | I16: =H16*365 -> 8508.9576 | L16: Run-rate = mean daily effective cost over the 84 days before the action, the same window the estimator uses.
A17: i-093 | B17: r-0155 | C17: bu-assist | D17: schedule_shutdown | E17: 45824 | F17: 2.6764013 | G17: 40 | H17: 2.108424 | I17: =H17*365 -> 769.57477
A18: i-019 | B18: r-0041 | C18: bu-search | D18: schedule_shutdown | E18: 45825 | F18: 0.79736558 | G18: 40 | H18: 98.729541 | I18: =H18*365 -> 36036.283
A19: i-043 | B19: r-0375 | C19: bu-platform | D19: enable_autoscaling | E19: 45826 | F19: 0.65251775 | G19: 40 | H19: 58.561577 | I19: =H19*365 -> 21374.976
A20: i-034 | B20: r-0314 | C20: bu-assist | D20: enable_autoscaling | E20: 45828 | F20: 0.69057882 | G20: 40 | H20: 448.78342 | I20: =H20*365 -> 163805.95
A21: i-055 | B21: r-0376 | C21: bu-datalake | D21: cache_inference_results | E21: 45828 | F21: 0.55398301 | G21: 40 | H21: 193.65231 | I21: =H21*365 -> 70683.093
A22: i-036 | B22: r-0350 | C22: bu-assist | D22: rightsize_instance | E22: 45831 | F22: 0.68710147 | G22: 40 | H22: 8.9017495 | I22: =H22*365 -> 3249.1386
A23: i-003 | B23: r-0092 | C23: bu-checkout | D23: delete_orphaned_volume | E23: 45832 | F23: 0.99799938 | G23: 40 | H23: 253.43038 | I23: =H23*365 -> 92502.089
A24: i-111 | B24: r-0282 | C24: bu-checkout | D24: rightsize_instance | E24: 45841 | F24: 2.4319834 | G24: 40 | H24: 14.88424 | I24: =H24*365 -> 5432.7477
A25: i-015 | B25: r-0131 | C25: bu-platform | D25: enable_autoscaling | E25: 45842 | F25: 0.85325146 | G25: 40 | H25: 8.1295874 | I25: =H25*365 -> 2967.2994
A26: i-054 | B26: r-0255 | C26: bu-datalake | D26: migrate_storage_class | E26: 45846 | F26: 0.56649971 | G26: 40 | H26: 116.10159 | I26: =H26*365 -> 42377.08
A27: i-090 | B27: r-0000 | C27: bu-search | D27: migrate_storage_class | E27: 45848 | F27: 2.7565139 | G27: 40 | H27: 69.799614 | I27: =H27*365 -> 25476.859
A28: i-097 | B28: r-0005 | C28: bu-platform | D28: delete_orphaned_volume | E28: 45852 | F28: 2.5948097 | G28: 40 | H28: 21.633101 | I28: =H28*365 -> 7896.0818
... A122: i-108 | B122: r-0087 | C122: bu-search | D122: schedule_shutdown | E122: 46150 | F122: 2.468269 | G122: 40 | H122: 48.97083 | I122: =H122*365 -> 17874.353

Sheet 04 Savings Attribution
A1: Savings attribution
A2: What each event is credited with, on what evidence. Before/after is what the industry reports; the identified estimate is difference-in-differences with randomisation inference; the parallel-trends check decides whether it is credible.
A3: SIMULATED DATA. The estate is synthetic (FOCUS 1.2, 400 resources, 540 days). Figures illustrate the method; ground truth exists only because the data is simulated.
A4: Peach columns use ground truth, which exists only because the estate is simulated. A real deployment would not have them -- that is the point of needing an estimator at all.
A5: Event | B5: Business unit | C5: Action | D5: Annualised run-rate | E5: Before/after effect (log) | F5: Before/after annual $ | G5: Identified effect (log) | H5: CI low | I5: CI high | J5: p-value | K5: Parallel trends passed | L5: Credited? | M5: Identified annual $ | N5: Credited annual $ | O5: SIMULATED true effect (log) | P5: SIMULATED true annual $ | Q5: |Before/after − true| | R5: Null event?
A6: ='03 Optimization Events'!A6 -> i-114 | B6: ='03 Optimization Events'!C6 -> bu-search | C6: ='03 Optimization Events'!D6 -> delete_orphaned_volume | D6: ='03 Optimization Events'!I6 -> 45751.417 | E6: -0.1018259 | F6: =-(EXP(E6)-1)*D6 -> 4429.342 | G6: -0.19258744 | H6: =EXP(-0.459706669454089)-1 -> -0.36853115 | I6: =EXP(0.0745317882950329)-1 -> 0.077379591 | J6: 0.17073171 | K6: =TRUE() -> TRUE | L6: =IF('10 Assumptions'!$B$24="Yes",TRUE(),K6) -> TRUE | M6: =-(EXP(G6)-1)*D6 -> 8014.6329 | N6: =IF(L6,M6,0) -> 8014.6329 | O6: 0 | P6: =-(EXP(O6)-1)*D6 -> 0 | Q6: =ABS(F6-P6) -> 4429.342 | R6: =TRUE() -> TRUE
A7: ='03 Optimization Events'!A7 -> i-028 | B7: ='03 Optimization Events'!C7 -> bu-datasci | C7: ='03 Optimization Events'!D7 -> delete_orphaned_volume | D7: ='03 Optimization Events'!I7 -> 7320.639 | E7: -1.111053 | F7: =-(EXP(E7)-1)*D7 -> 4910.5959 | G7: -1.1042475 | H7: =EXP(-1.47780584943431)-1 -> -0.77186229 | I7: =EXP(-0.730689203597679)-1 -> -0.51842303 | J7: 0.024390244 | K7: =TRUE() -> TRUE | L7: =IF('10 Assumptions'!$B$24="Yes",TRUE(),K7) -> TRUE | M7: =-(EXP(G7)-1)*D7 -> 4894.1385 | N7: =IF(L7,M7,0) -> 4894.1385 | O7: -0.94161877 | P7: =-(EXP(O7)-1)*D7 -> 4465.619 | Q7: =ABS(F7-P7) -> 444.97693 | R7: =FALSE() -> FALSE
A8: ='03 Optimization Events'!A8 -> i-088 | B8: ='03 Optimization Events'!C8 -> bu-platform | C8: ='03 Optimization Events'!D8 -> cache_inference_results | D8: ='03 Optimization Events'!I8 -> 3227.6889 | E8: 0.082522121 | F8: =-(EXP(E8)-1)*D8 -> -277.6545 | G8: -0.0040726654 | H8: =EXP(-0.236238693848157)-1 -> -0.21040782 | I8: =EXP(0.228093363012354)-1 -> 0.2562026 | J8: 0.95121951 | K8: =TRUE() -> TRUE | L8: =IF('10 Assumptions'!$B$24="Yes",TRUE(),K8) -> TRUE | M8: =-(EXP(G8)-1)*D8 -> 13.118565 | N8: =IF(L8,M8,0) -> 13.118565 | O8: 0 | P8: =-(EXP(O8)-1)*D8 -> 0 | Q8: =ABS(F8-P8) -> 277.6545 | R8: =TRUE() -> TRUE
A9: ='03 Optimization Events'!A9 -> i-027 | B9: ='03 Optimization Events'!C9 -> bu-platform | C9: ='03 Optimization Events'!D9 -> cache_inference_results | D9: ='03 Optimization Events'!I9 -> 17214.867 | E9: -0.59643523 | F9: =-(EXP(E9)-1)*D9 -> 7733.4087 | G9: -0.69141514 | H9: =EXP(-0.94473403500977)-1 -> -0.61121704 | I9: =EXP(-0.438096243067447)-1 -> -0.35473632 | J9: 0.024390244 | K9: =TRUE() -> TRUE | L9: =IF('10 Assumptions'!$B$24="Yes",TRUE(),K9) -> TRUE | M9: =-(EXP(G9)-1)*D9 -> 8592.5122 | N9: =IF(L9,M9,0) -> 8592.5122 | O9: -1.0258456 | P9: =-(EXP(O9)-1)*D9 -> 11043.454 | Q9: =ABS(F9-P9) -> 3310.0457 | R9: =FALSE() -> FALSE
A10: ='03 Optimization Events'!A10 -> i-030 | B10: ='03 Optimization Events'!C10 -> bu-checkout | C10: ='03 Optimization Events'!D10 -> enable_autoscaling | D10: ='03 Optimization Events'!I10 -> 24332.034 | E10: -1.0068344 | F10: =-(EXP(E10)-1)*D10 -> 15441.747 | G10: -1.0603992 | H10: =EXP(-1.3078909391039)-1 -> -0.72961028 | I10: =EXP(-0.812907457209481)-1 -> -0.55643346 | J10: 0.024390244 | K10: =TRUE() -> TRUE | L10: =IF('10 Assumptions'!$B$24="Yes",TRUE(),K10) -> TRUE | M10: =-(EXP(G10)-1)*D10 -> 15905.424 | N10: =IF(L10,M10,0) -> 15905.424 | O10: -0.960414 | P10: =-(EXP(O10)-1)*D10 -> 15019.328 | Q10: =ABS(F10-P10) -> 422.41881 | R10: =FALSE() -> FALSE
A11: ='03 Optimization Events'!A11 -> i-049 | B11: ='03 Optimization Events'!C11 -> bu-checkout | C11: ='03 Optimization Events'!D11 -> cache_inference_results | D11: ='03 Optimization Events'!I11 -> 66691.642 | E11: -0.83427843 | F11: =-(EXP(E11)-1)*D11 -> 37734.953 | G11: -0.88509515 | H11: =EXP(-1.08292600132974)-1 -> -0.66139668 | I11: =EXP(-0.687264307105471)-1 -> -0.49704989 | J11: 0.024390244 | K11: =TRUE() -> TRUE | L11: =IF('10 Assumptions'!$B$24="Yes",TRUE(),K11) -> TRUE | M11: =-(EXP(G11)-1)*D11 -> 39169.675 | N11: =IF(L11,M11,0) -> 39169.675 | O11: -0.90210242 | P11: =-(EXP(O11)-1)*D11 -> 39633.79 | Q11: =ABS(F11-P11) -> 1898.837 | R11: =FALSE() -> FALSE
A12: ='03 Optimization Events'!A12 -> i-029 | B12: ='03 Optimization Events'!C12 -> bu-platform | C12: ='03 Optimization Events'!D12 -> tune_batch_size | D12: ='03 Optimization Events'!I12 -> 9034.1356 | E12: -0.70813382 | F12: =-(EXP(E12)-1)*D12 -> 4584.2587 | G12: -0.65936562 | H12: =EXP(-0.981535275628546)-1 -> -0.62526467 | I12: =EXP(-0.337195956285617)-1 -> -0.28623104 | J12: 0.024390244 | K12: =TRUE() -> TRUE | L12: =IF('10 Assumptions'!$B$24="Yes",TRUE(),K12) -> TRUE | M12: =-(EXP(G12)-1)*D12 -> 4361.8675 | N12: =IF(L12,M12,0) -> 4361.8675 | O12: -0.78101059 | P12: =-(EXP(O12)-1)*D12 -> 4897.0166 | Q12: =ABS(F12-P12) -> 312.75786 | R12: =FALSE() -> FALSE
A13: ='03 Optimization Events'!A13 -> i-011 | B13: ='03 Optimization Events'!C13 -> bu-datalake | C13: ='03 Optimization Events'!D13 -> consolidate_cluster | D13: ='03 Optimization Events'!I13 -> 23461.885 | E13: -1.2933233 | F13: =-(EXP(E13)-1)*D13 -> 17024.941 | G13: -1.2686402 | H13: =EXP(-1.65030056852937)-1 -> -0.80800781 | I13: =EXP(-0.886979798820441)-1 -> -0.58810211 | J13: 0.024390244 | K13: =TRUE() -> TRUE | L13: =IF('10 Assumptions'!$B$24="Yes",TRUE(),K13) -> TRUE | M13: =-(EXP(G13)-1)*D13 -> 16864.08 | N13: =IF(L13,M13,0) -> 16864.08 | O13: -1.2375593 | P13: =-(EXP(O13)-1)*D13 -> 16655.795 | Q13: =ABS(F13-P13) -> 369.14633 | R13: =FALSE() -> FALSE
A14: ='03 Optimization Events'!A14 -> i-014 | B14: ='03 Optimization Events'!C14 -> bu-assist | C14: ='03 Optimization Events'!D14 -> migrate_storage_class | D14: ='03 Optimization Events'!I14 -> 162453.13 | E14: -1.2301074 | F14: =-(EXP(E14)-1)*D14 -> 114974.38 | G14: -1.1727474 | H14: =EXP(-1.59372946483018)-1 -> -0.79683351 | I14: =EXP(-0.751765345174508)-1 -> -0.5284666 | J14: 0.024390244 | K14: =TRUE() -> TRUE | L14: =IF('10 Assumptions'!$B$24="Yes",TRUE(),K14) -> TRUE | M14: =-(EXP(G14)-1)*D14 -> 112171.38 | N14: =IF(L14,M14,0) -> 112171.38 | O14: -1.0058833 | P14: =-(EXP(O14)-1)*D14 -> 103040.53 | Q14: =ABS(F14-P14) -> 11933.849 | R14: =FALSE() -> FALSE
A15: ='03 Optimization Events'!A15 -> i-042 | B15: ='03 Optimization Events'!C15 -> bu-search | C15: ='03 Optimization Events'!D15 -> enable_autoscaling | D15: ='03 Optimization Events'!I15 -> 17475.441 | E15: -0.44275322 | F15: =-(EXP(E15)-1)*D15 -> 6251.5651 | G15: -0.41317792 | H15: =EXP(-0.842249150766249)-1 -> -0.56925937 | I15: =EXP(0.0158933191841399)-1 -> 0.01602029 | J15: 0.12195122 | K15: =FALSE() -> FALSE | L15: =IF('10 Assumptions'!$B$24="Yes",TRUE(),K15) -> FALSE | M15: =-(EXP(G15)-1)*D15 -> 5914.658 | N15: =IF(L15,M15,0) -> 0 | O15: -0.72587963 | P15: =-(EXP(O15)-1)*D15 -> 9019.0975 | Q15: =ABS(F15-P15) -> 2767.5324 | R15: =FALSE() -> FALSE
A16: ='03 Optimization Events'!A16 -> i-067 | B16: ='03 Optimization Events'!C16 -> bu-assist | C16: ='03 Optimization Events'!D16 -> consolidate_cluster | D16: ='03 Optimization Events'!I16 -> 8508.9576 | E16: -0.62766739 | F16: =-(EXP(E16)-1)*D16 -> 3966.5733 | G16: -0.57325453 | H16: =EXP(-0.993374541074759)-1 -> -0.6296751 | I16: =EXP(-0.153134515973858)-1 -> -0.1419857 | J16: 0.024390244 | K16: =TRUE() -> TRUE | L16: =IF('10 Assumptions'!$B$24="Yes",TRUE(),K16) -> TRUE | M16: =-(EXP(G16)-1)*D16 -> 3712.5611 | N16: =IF(L16,M16,0) -> 3712.5611 | O16: -0.83057537 | P16: =-(EXP(O16)-1)*D16 -> 4800.7669 | Q16: =ABS(F16-P16) -> 834.19363 | R16: =FALSE() -> FALSE
A17: ='03 Optimization Events'!A17 -> i-093 | B17: ='03 Optimization Events'!C17 -> bu-assist | C17: ='03 Optimization Events'!D17 -> schedule_shutdown | D17: ='03 Optimization Events'!I17 -> 769.57477 | E17: 0.67254197 | F17: =-(EXP(E17)-1)*D17 -> -738.18479 | G17: 0.69502651 | H17: =EXP(0.267326956452451)-1 -> 0.30646753 | I17: =EXP(1.12272606426671)-1 -> 2.0732206 | J17: 0.024390244 | K17: =FALSE() -> FALSE | L17: =IF('10 Assumptions'!$B$24="Yes",TRUE(),K17) -> FALSE | M17: =-(EXP(G17)-1)*D17 -> -772.47006 | N17: =IF(L17,M17,0) -> 0 | O17: 0 | P17: =-(EXP(O17)-1)*D17 -> 0 | Q17: =ABS(F17-P17) -> 738.18479 | R17: =TRUE() -> TRUE
A18: ='03 Optimization Events'!A18 -> i-019 | B18: ='03 Optimization Events'!C18 -> bu-search | C18: ='03 Optimization Events'!D18 -> schedule_shutdown | D18: ='03 Optimization Events'!I18 -> 36036.283 | E18: -0.80533933 | F18: =-(EXP(E18)-1)*D18 -> 19930.362 | G18: -0.89976003 | H18: =EXP(-1.08969635379483)-1 -> -0.6636814 | I18: =EXP(-0.709823699894466)-1 -> -0.50826912 | J18: 0.024390244 | K18: =TRUE() -> TRUE | L18: =IF('10 Assumptions'!$B$24="Yes",TRUE(),K18) -> TRUE | M18: =-(EXP(G18)-1)*D18 -> 21381.507 | N18: =IF(L18,M18,0) -> 21381.507 | O18: -0.86920234 | P18: =-(EXP(O18)-1)*D18 -> 20926.779 | Q18: =ABS(F18-P18) -> 996.41676 | R18: =FALSE() -> FALSE
A19: ='03 Optimization Events'!A19 -> i-043 | B19: ='03 Optimization Events'!C19 -> bu-platform | C19: ='03 Optimization Events'!D19 -> enable_autoscaling | D19: ='03 Optimization Events'!I19 -> 21374.976 | E19: -0.60170707 | F19: =-(EXP(E19)-1)*D19 -> 9664.1485 | G19: -0.64540852 | H19: =EXP(-0.894314900052785)-1 -> -0.59111237 | I19: =EXP(-0.39650214473697)-1 -> -0.32733117 | J19: 0.024390244 | K19: =TRUE() -> TRUE | L19: =IF('10 Assumptions'!$B$24="Yes",TRUE(),K19) -> TRUE | M19: =-(EXP(G19)-1)*D19 -> 10164.907 | N19: =IF(L19,M19,0) -> 10164.907 | O19: -0.85609698 | P19: =-(EXP(O19)-1)*D19 -> 12294.524 | Q19: =ABS(F19-P19) -> 2630.3758 | R19: =FALSE() -> FALSE
A20: ='03 Optimization Events'!A20 -> i-034 | B20: ='03 Optimization Events'!C20 -> bu-assist | C20: ='03 Optimization Events'!D20 -> enable_autoscaling | D20: ='03 Optimization Events'!I20 -> 163805.95 | E20: -0.38426936 | F20: =-(EXP(E20)-1)*D20 -> 52262.619 | G20: -0.36486612 | H20: =EXP(-0.807185402010445)-1 -> -0.55388807 | I20: =EXP(0.0774531573204561)-1 -> 0.080531616 | J20: 0.19512195 | K20: =FALSE() -> FALSE | L20: =IF('10 Assumptions'!$B$24="Yes",TRUE(),K20) -> FALSE | M20: =-(EXP(G20)-1)*D20 -> 50077.183 | N20: =IF(L20,M20,0) -> 0 | O20: -0.77597352 | P20: =-(EXP(O20)-1)*D20 -> 88413.361 | Q20: =ABS(F20-P20) -> 36150.742 | R20: =FALSE() -> FALSE
A21: ='03 Optimization Events'!A21 -> i-055 | B21: ='03 Optimization Events'!C21 -> bu-datalake | C21: ='03 Optimization Events'!D21 -> cache_inference_results | D21: ='03 Optimization Events'!I21 -> 70683.093 | E21: -0.78331463 | F21: =-(EXP(E21)-1)*D21 -> 38388.759 | G21: -0.78998953 | H21: =EXP(-1.10274952830287)-1 -> -0.6680429 | I21: =EXP(-0.47722952854347)-1 -> -0.37949991 | J21: 0.024390244 | K21: =TRUE() -> TRUE | L21: =IF('10 Assumptions'!$B$24="Yes",TRUE(),K21) -> TRUE | M21: =-(EXP(G21)-1)*D21 -> 38603.603 | N21: =IF(L21,M21,0) -> 38603.603 | O21: -0.82358533 | P21: =-(EXP(O21)-1)*D21 -> 39663.437 | Q21: =ABS(F21-P21) -> 1274.6773 | R21: =FALSE() -> FALSE
A22: ='03 Optimization Events'!A22 -> i-036 | B22: ='03 Optimization Events'!C22 -> bu-assist | C22: ='03 Optimization Events'!D22 -> rightsize_instance | D22: ='03 Optimization Events'!I22 -> 3249.1386 | E22: -1.2255938 | F22: =-(EXP(E22)-1)*D22 -> 2295.2457 | G22: -1.2088499 | H22: =EXP(-1.43907270289978)-1 -> -0.76285244 | I22: =EXP(-0.978627170355868)-1 -> -0.62417331 | J22: 0.024390244 | K22: =TRUE() -> TRUE | L22: =IF('10 Assumptions'!$B$24="Yes",TRUE(),K22) -> TRUE | M22: =-(EXP(G22)-1)*D22 -> 2279.1394 | N22: =IF(L22,M22,0) -> 2279.1394 | O22: -1.0937074 | P22: =-(EXP(O22)-1)*D22 -> 2160.7671 | Q22: =ABS(F22-P22) -> 134.47859 | R22: =FALSE() -> FALSE
A23: ='03 Optimization Events'!A23 -> i-003 | B23: ='03 Optimization Events'!C23 -> bu-checkout | C23: ='03 Optimization Events'!D23 -> delete_orphaned_volume | D23: ='03 Optimization Events'!I23 -> 92502.089 | E23: -1.1978992 | F23: =-(EXP(E23)-1)*D23 -> 64582.402 | G23: -1.2453427 | H23: =EXP(-1.49428739641576)-1 -> -0.77559154 | I23: =EXP(-0.996397963183087)-1 -> -0.63079305 | J23: 0.024390244 | K23: =TRUE() -> TRUE | L23: =IF('10 Assumptions'!$B$24="Yes",TRUE(),K23) -> TRUE | M23: =-(EXP(G23)-1)*D23 -> 65876.079 | N23: =IF(L23,M23,0) -> 65876.079 | O23: -1.2483525 | P23: =-(EXP(O23)-1)*D23 -> 65956.097 | Q23: =ABS(F23-P23) -> 1373.695 | R23: =FALSE() -> FALSE
A24: ='03 Optimization Events'!A24 -> i-111 | B24: ='03 Optimization Events'!C24 -> bu-checkout | C24: ='03 Optimization Events'!D24 -> rightsize_instance | D24: ='03 Optimization Events'!I24 -> 5432.7477 | E24: -0.02872515 | F24: =-(EXP(E24)-1)*D24 -> 153.83643 | G24: -0.10681438 | H24: =EXP(-0.272007869891729)-1 -> -0.23815173 | I24: =EXP(0.0583791157011727)-1 -> 0.060116826 | J24: 0.24390244 | K24: =FALSE() -> FALSE | L24: =IF('10 Assumptions'!$B$24="Yes",TRUE(),K24) -> FALSE | M24: =-(EXP(G24)-1)*D24 -> 550.37822 | N24: =IF(L24,M24,0) -> 0 | O24: 0 | P24: =-(EXP(O24)-1)*D24 -> 0 | Q24: =ABS(F24-P24) -> 153.83643 | R24: =TRUE() -> TRUE
A25: ='03 Optimization Events'!A25 -> i-015 | B25: ='03 Optimization Events'!C25 -> bu-platform | C25: ='03 Optimization Events'!D25 -> enable_autoscaling | D25: ='03 Optimization Events'!I25 -> 2967.2994 | E25: -1.0403725 | F25: =-(EXP(E25)-1)*D25 -> 1918.8842 | G25: -1.0226787 | H25: =EXP(-1.27906004265867)-1 -> -0.72170123 | I25: =EXP(-0.766297445158814)-1 -> -0.53526942 | J25: 0.024390244 | K25: =TRUE() -> TRUE | L25: =IF('10 Assumptions'!$B$24="Yes",TRUE(),K25) -> TRUE | M25: =-(EXP(G25)-1)*D25 -> 1900.1687 | N25: =IF(L25,M25,0) -> 1900.1687 | O25: -1.1358284 | P25: =-(EXP(O25)-1)*D25 -> 2014.3335 | Q25: =ABS(F25-P25) -> 95.449299 | R25: =FALSE() -> FALSE
A26: ='03 Optimization Events'!A26 -> i-054 | B26: ='03 Optimization Events'!C26 -> bu-datalake | C26: ='03 Optimization Events'!D26 -> migrate_storage_class | D26: ='03 Optimization Events'!I26 -> 42377.08 | E26: -1.0294728 | F26: =-(EXP(E26)-1)*D26 -> 27240.189 | G26: -1.0634189 | H26: =EXP(-1.39852654753326)-1 -> -0.75303942 | I26: =EXP(-0.728311244810419)-1 -> -0.5172765 | J26: 0.024390244 | K26: =TRUE() -> TRUE | L26: =IF('10 Assumptions'!$B$24="Yes",TRUE(),K26) -> TRUE | M26: =-(EXP(G26)-1)*D26 -> 27745.404 | N26: =IF(L26,M26,0) -> 27745.404 | O26: -0.90785851 | P26: =-(EXP(O26)-1)*D26 -> 25282.71 | Q26: =ABS(F26-P26) -> 1957.4783 | R26: =FALSE() -> FALSE
A27: ='03 Optimization Events'!A27 -> i-090 | B27: ='03 Optimization Events'!C27 -> bu-search | C27: ='03 Optimization Events'!D27 -> migrate_storage_class | D27: ='03 Optimization Events'!I27 -> 25476.859 | E27: 0.17652457 | F27: =-(EXP(E27)-1)*D27 -> -4918.6578 | G27: 0.14463481 | H27: =EXP(-0.0914332288552578)-1 -> -0.087377749 | I27: =EXP(0.380702852991075)-1 -> 0.46331272 | J27: 0.14634146 | K27: =TRUE() -> TRUE | L27: =IF('10 Assumptions'!$B$24="Yes",TRUE(),K27) -> TRUE | M27: =-(EXP(G27)-1)*D27 -> -3964.6445 | N27: =IF(L27,M27,0) -> -3964.6445 | O27: 0 | P27: =-(EXP(O27)-1)*D27 -> 0 | Q27: =ABS(F27-P27) -> 4918.6578 | R27: =TRUE() -> TRUE
A28: ='03 Optimization Events'!A28 -> i-097 | B28: ='03 Optimization Events'!C28 -> bu-platform | C28: ='03 Optimization Events'!D28 -> delete_orphaned_volume | D28: ='03 Optimization Events'!I28 -> 7896.0818 | E28: 0.083566987 | F28: =-(EXP(E28)-1)*D28 -> -688.207 | G28: 0.031886179 | H28: =EXP(-0.292498788829419)-1 -> -0.25360385 | I28: =EXP(0.356271146249154)-1 -> 0.42799469 | J28: 0.95121951 | K28: =TRUE() -> TRUE | L28: =IF('10 Assumptions'!$B$24="Yes",TRUE(),K28) -> TRUE | M28: =-(EXP(G28)-1)*D28 -> -255.83297 | N28: =IF(L28,M28,0) -> -255.83297 | O28: 0 | P28: =-(EXP(O28)-1)*D28 -> 0 | Q28: =ABS(F28-P28) -> 688.207 | R28: =TRUE() -> TRUE
A29: ='03 Optimization Events'!A29 -> i-075 | B29: ='03 Optimization Events'!C29 -> bu-platform | C29: ='03 Optimization Events'!D29 -> tune_batch_size | D29: ='03 Optimization Events'!I29 -> 7165.3189 | E29: -0.56318877 | F29: =-(EXP(E29)-1)*D29 -> 3085.4543 | G29: -0.59799103 | H29: =EXP(-0.82865767349973)-1 -> -0.563365 | I29: =EXP(-0.367324393786616)-1 -> -0.30741506 | J29: 0.024390244 | K29: =TRUE() -> TRUE | L29: =IF('10 Assumptions'!$B$24="Yes",TRUE(),K29) -> TRUE | M29: =-(EXP(G29)-1)*D29 -> 3225.0005 | N29: =IF(L29,M29,0) -> 3225.0005 | O29: -0.58631919 | P29: =-(EXP(O29)-1)*D29 -> 3178.7403 | Q29: =ABS(F29-P29) -> 93.285938 | R29: =FALSE() -> FALSE
A30: ='03 Optimization Events'!A30 -> i-070 | B30: ='03 Optimization Events'!C30 -> bu-search | C30: ='03 Optimization Events'!D30 -> migrate_storage_class | D30: ='03 Optimization Events'!I30 -> 15149.339 | E30: -0.62345999 | F30: =-(EXP(E30)-1)*D30 -> 7027.9848 | G30: -0.60291621 | H30: =EXP(-0.851655304037839)-1 -> -0.57329198 | I30: =EXP(-0.354177109585918)-1 -> -0.29824933 | J30: 0.024390244 | K30: =TRUE() -> TRUE | L30: =IF('10 Assumptions'!$B$24="Yes",TRUE(),K30) -> TRUE | M30: =-(EXP(G30)-1)*D30 -> 6859.4158 | N30: =IF(L30,M30,0) -> 6859.4158 | O30: -0.61376735 | P30: =-(EXP(O30)-1)*D30 -> 6948.8847 | Q30: =ABS(F30-P30) -> 79.100081 | R30: =FALSE() -> FALSE
A31: ='03 Optimization Events'!A31 -> i-079 | B31: ='03 Optimization Events'!C31 -> bu-datasci | C31: ='03 Optimization Events'!D31 -> consolidate_cluster | D31: ='03 Optimization Events'!I31 -> 24354.612 | E31: -0.71271701 | F31: =-(EXP(E31)-1)*D31 -> 12413.297 | G31: -0.67857179 | H31: =EXP(-0.973573708624723)-1 -> -0.62226928 | I31: =EXP(-0.383569861668891)-1 -> -0.31857553 | J31: 0.024390244 | K31: =TRUE() -> TRUE | L31: =IF('10 Assumptions'!$B$24="Yes",TRUE(),K31) -> TRUE | M31: =-(EXP(G31)-1)*D31 -> 11998.517 | N31: =IF(L31,M31,0) -> 11998.517 | O31: -0.61785884 | P31: =-(EXP(O31)-1)*D31 -> 11225.102 | Q31: =ABS(F31-P31) -> 1188.1955 | R31: =FALSE() -> FALSE
A32: ='03 Optimization Events'!A32 -> i-005 | B32: ='03 Optimization Events'!C32 -> bu-platform | C32: ='03 Optimization Events'!D32 -> tune_batch_size | D32: ='03 Optimization Events'!I32 -> 16912.919 | E32: -0.82039874 | F32: =-(EXP(E32)-1)*D32 -> 9466.9035 | G32: -0.82625157 | H32: =EXP(-1.11231679036596)-1 -> -0.67120367 | I32: =EXP(-0.540186357433524)-1 -> -0.41736034 | J32: 0.024390244 | K32: =TRUE() -> TRUE | L32: =IF('10 Assumptions'!$B$24="Yes",TRUE(),K32) -> TRUE | M32: =-(EXP(G32)-1)*D32 -> 9510.3565 | N32: =IF(L32,M32,0) -> 9510.3565 | O32: -1.0556884 | P32: =-(EXP(O32)-1)*D32 -> 11028.021 | Q32: =ABS(F32-P32) -> 1561.1176 | R32: =FALSE() -> FALSE
A33: ='03 Optimization Events'!A33 -> i-002 | B33: ='03 Optimization Events'!C33 -> bu-checkout | C33: ='03 Optimization Events'!D33 -> tune_batch_size | D33: ='03 Optimization Events'!I33 -> 11589.513 | E33: -1.133623 | F33: =-(EXP(E33)-1)*D33 -> 7859.2541 | G33: -1.1807293 | H33: =EXP(-1.45450359792976)-1 -> -0.76648375 | I33: =EXP(-0.906955056912496)-1 -> -0.59624824 | J33: 0.024390244 | K33: =TRUE() -> TRUE | L33: =IF('10 Assumptions'!$B$24="Yes",TRUE(),K33) -> TRUE | M33: =-(EXP(G33)-1)*D33 -> 8030.8986 | N33: =IF(L33,M33,0) -> 8030.8986 | O33: -1.3353975 | P33: =-(EXP(O33)-1)*D33 -> 8540.8502 | Q33: =ABS(F33-P33) -> 681.59611 | R33: =FALSE() -> FALSE
A34: ='03 Optimization Events'!A34 -> i-026 | B34: ='03 Optimization Events'!C34 -> bu-search | C34: ='03 Optimization Events'!D34 -> enable_autoscaling | D34: ='03 Optimization Events'!I34 -> 4349.0941 | E34: -0.77409375 | F34: =-(EXP(E34)-1)*D34 -> 2343.6334 | G34: -0.7994295 | H34: =EXP(-1.08646207121041)-1 -> -0.66259189 | I34: =EXP(-0.512396918988007)-1 -> -0.40094204 | J34: 0.024390244 | K34: =TRUE() -> TRUE | L34: =IF('10 Assumptions'!$B$24="Yes",TRUE(),K34) -> TRUE | M34: =-(EXP(G34)-1)*D34 -> 2393.805 | N34: =IF(L34,M34,0) -> 2393.805 | O34: -0.92327601 | P34: =-(EXP(O34)-1)*D34 -> 2621.566 | Q34: =ABS(F34-P34) -> 277.9326 | R34: =FALSE() -> FALSE
A35: ='03 Optimization Events'!A35 -> i-076 | B35: ='03 Optimization Events'!C35 -> bu-datasci | C35: ='03 Optimization Events'!D35 -> rightsize_instance | D35: ='03 Optimization Events'!I35 -> 139435.03 | E35: -0.36768334 | F35: =-(EXP(E35)-1)*D35 -> 42899.086 | G35: -0.28204118 | H35: =EXP(-0.593903561551567)-1 -> -0.44783235 | I35: =EXP(0.0298212106553653)-1 -> 0.030270316 | J35: 0.073170732 | K35: =TRUE() -> TRUE | L35: =IF('10 Assumptions'!$B$24="Yes",TRUE(),K35) -> TRUE | M35: =-(EXP(G35)-1)*D35 -> 34267.187 | N35: =IF(L35,M35,0) -> 34267.187 | O35: -0.40393074 | P35: =-(EXP(O35)-1)*D35 -> 46335.605 | Q35: =ABS(F35-P35) -> 3436.5186 | R35: =FALSE() -> FALSE
A36: ='03 Optimization Events'!A36 -> i-056 | B36: ='03 Optimization Events'!C36 -> bu-search | C36: ='03 Optimization Events'!D36 -> migrate_storage_class | D36: ='03 Optimization Events'!I36 -> 7423.0138 | E36: -0.35282599 | F36: =-(EXP(E36)-1)*D36 -> 2206.866 | G36: -0.42827614 | H36: =EXP(-0.819109698773683)-1 -> -0.55917605 | I36: =EXP(-0.0374425755300337)-1 -> -0.03675027 | J36: 0.12195122 | K36: =FALSE() -> FALSE | L36: =IF('10 Assumptions'!$B$24="Yes",TRUE(),K36) -> FALSE | M36: =-(EXP(G36)-1)*D36 -> 2585.9445 | N36: =IF(L36,M36,0) -> 0 | O36: -0.65934113 | P36: =-(EXP(O36)-1)*D36 -> 3583.8906 | Q36: =ABS(F36-P36) -> 1377.0246 | R36: =FALSE() -> FALSE
A37: ='03 Optimization Events'!A37 -> i-035 | B37: ='03 Optimization Events'!C37 -> bu-platform | C37: ='03 Optimization Events'!D37 -> consolidate_cluster | D37: ='03 Optimization Events'!I37 -> 10768.238 | E37: -0.96709449 | F37: =-(EXP(E37)-1)*D37 -> 6674.304 | G37: -0.93369618 | H37: =EXP(-1.31344241563948)-1 -> -0.73110718 | I37: =EXP(-0.553949937313814)-1 -> -0.42532461 | J37: 0.024390244 | K37: =TRUE() -> TRUE | L37: =IF('10 Assumptions'!$B$24="Yes",TRUE(),K37) -> TRUE | M37: =-(EXP(G37)-1)*D37 -> 6535.2646 | N37: =IF(L37,M37,0) -> 6535.2646 | O37: -1.0040153 | P37: =-(EXP(O37)-1)*D37 -> 6822.6991 | Q37: =ABS(F37-P37) -> 148.39512 | R37: =FALSE() -> FALSE
A38: ='03 Optimization Events'!A38 -> i-044 | B38: ='03 Optimization Events'!C38 -> bu-search | C38: ='03 Optimization Events'!D38 -> enable_autoscaling | D38: ='03 Optimization Events'!I38 -> 13007.061 | E38: -0.8250467 | F38: =-(EXP(E38)-1)*D38 -> 7307.178 | G38: -0.84960215 | H38: =EXP(-1.03819559800658)-1 -> -0.64590697 | I38: =EXP(-0.661008702523781)-1 -> -0.48366975 | J38: 0.024390244 | K38: =TRUE() -> TRUE | L38: =IF('10 Assumptions'!$B$24="Yes",TRUE(),K38) -> TRUE | M38: =-(EXP(G38)-1)*D38 -> 7445.4367 | N38: =IF(L38,M38,0) -> 7445.4367 | O38: -0.85787993 | P38: =-(EXP(O38)-1)*D38 -> 7491.2846 | Q38: =ABS(F38-P38) -> 184.10662 | R38: =FALSE() -> FALSE
A39: ='03 Optimization Events'!A39 -> i-094 | B39: ='03 Optimization Events'!C39 -> bu-platform | C39: ='03 Optimization Events'!D39 -> tune_batch_size | D39: ='03 Optimization Events'!I39 -> 61120.375 | E39: 0.094824384 | F39: =-(EXP(E39)-1)*D39 -> -6079.3842 | G39: -0.012108413 | H39: =EXP(-0.419832833021877)-1 -> -0.34284333 | I39: =EXP(0.395616007330647)-1 -> 0.48529886 | J39: 0.87804878 | K39: =TRUE() -> TRUE | L39: =IF('10 Assumptions'!$B$24="Yes",TRUE(),K39) -> TRUE | M39: =-(EXP(G39)-1)*D39 -> 735.60822 | N39: =IF(L39,M39,0) -> 735.60822 | O39: 0 | P39: =-(EXP(O39)-1)*D39 -> 0 | Q39: =ABS(F39-P39) -> 6079.3842 | R39: =TRUE() -> TRUE
A40: ='03 Optimization Events'!A40 -> i-080 | B40: ='03 Optimization Events'!C40 -> bu-checkout | C40: ='03 Optimization Events'!D40 -> schedule_shutdown | D40: ='03 Optimization Events'!I40 -> 9665.808 | E40: -0.47328806 | F40: =-(EXP(E40)-1)*D40 -> 3644.4871 | G40: -0.5541449 | H40: =EXP(-0.709551548481789)-1 -> -0.50813527 | I40: =EXP(-0.398738246352189)-1 -> -0.32883364 | J40: 0.024390244 | K40: =TRUE() -> TRUE | L40: =IF('10 Assumptions'!$B$24="Yes",TRUE(),K40) -> TRUE | M40: =-(EXP(G40)-1)*D40 -> 4112.1889 | N40: =IF(L40,M40,0) -> 4112.1889 | O40: -0.47783794 | P40: =-(EXP(O40)-1)*D40 -> 3671.8212 | Q40: =ABS(F40-P40) -> 27.334059 | R40: =FALSE() -> FALSE
...

Sheet 05 Budget vs Actual
A1: Budget vs actual
A2: Budget = average of the first six complete months, grown monthly at the budget growth assumption. Actuals link to Raw Cost Data. Cost variance: under budget is favourable.
A3: SIMULATED DATA. The estate is synthetic (FOCUS 1.2, 400 resources, 540 days). Figures illustrate the method; ground truth exists only because the data is simulated.
A4: Monthly growth factor | B4: =(1+'10 Assumptions'!$B$20)^(1/12) -> 1.0117149 | C4: (1 + annual budget growth)^(1/12)
A5: Baseline (avg. months 1–6) | B5: =AVERAGE('02 Raw Cost Data'!I6:I11) -> 157209.37 | E5: =AVERAGE('02 Raw Cost Data'!J6:J11) -> 86225.561 | H5: =AVERAGE('02 Raw Cost Data'!K6:K11) -> 63959.106 | K5: =AVERAGE('02 Raw Cost Data'!L6:L11) -> 150202.68 | N5: =AVERAGE('02 Raw Cost Data'!M6:M11) -> 71068.818 | Q5: =AVERAGE('02 Raw Cost Data'!N6:N11) -> 86269.186 | T5: =AVERAGE('02 Raw Cost Data'!O6:O11) -> 74231.57
A6: Month | B6: bu-assist budget | C6: bu-assist actual | D6: bu-assist var | E6: bu-checkout budget | F6: bu-checkout actual | G6: bu-checkout var | H6: bu-datalake budget | I6: bu-datalake actual | J6: bu-datalake var | K6: bu-datasci budget | L6: bu-datasci actual | M6: bu-datasci var | N6: bu-platform budget | O6: bu-platform actual | P6: bu-platform var | Q6: bu-search budget | R6: bu-search actual | S6: bu-search var | T6: unallocated budget | U6: unallocated actual | V6: unallocated var | W6: Total budget | X6: Total actual | Y6: Total variance | Z6: Variance % | AA6: Status
A7: 45839 | B7: =$B$5*$B$4^1 -> 159051.06 | C7: ='02 Raw Cost Data'!I12 -> 157484.7 | D7: =C7-B7 -> -1566.3654 | E7: =$E$5*$B$4^1 -> 87235.687 | F7: ='02 Raw Cost Data'!J12 -> 93742.453 | G7: =F7-E7 -> 6506.7661 | H7: =$H$5*$B$4^1 -> 64708.381 | I7: ='02 Raw Cost Data'!K12 -> 71220.469 | J7: =I7-H7 -> 6512.0875 | K7: =$K$5*$B$4^1 -> 151962.29 | L7: ='02 Raw Cost Data'!L12 -> 154568.58 | M7: =L7-K7 -> 2606.2836 | N7: =$N$5*$B$4^1 -> 71901.384 | O7: ='02 Raw Cost Data'!M12 -> 70392.849 | P7: =O7-N7 -> -1508.5341 | Q7: =$Q$5*$B$4^1 -> 87279.823 | R7: ='02 Raw Cost Data'!N12 -> 97421.955 | S7: =R7-Q7 -> 10142.132 | T7: =$T$5*$B$4^1 -> 75101.187 | U7: ='02 Raw Cost Data'!O12 -> 78358.728 | V7: =U7-T7 -> 3257.5407 | W7: =B7+E7+H7+K7+N7+Q7+T7 -> 697239.81 | X7: =C7+F7+I7+L7+O7+R7+U7 -> 723189.72 | Y7: =X7-W7 -> 25949.91 | Z7: =IF(W7=0,0,Y7/W7) -> 0.037218056 | AA7: =IF(Z7>0.05,"Unfavourable",IF(Z7<-0.05,"Favourable","On plan")) -> On plan
A8: 45870 | B8: =$B$5*$B$4^2 -> 160914.33 | C8: ='02 Raw Cost Data'!I13 -> 164579.11 | D8: =C8-B8 -> 3664.775 | E8: =$E$5*$B$4^2 -> 88257.645 | F8: ='02 Raw Cost Data'!J13 -> 97362.162 | G8: =F8-E8 -> 9104.5163 | H8: =$H$5*$B$4^2 -> 65466.435 | I8: ='02 Raw Cost Data'!K13 -> 63816.123 | J8: =I8-H8 -> -1650.3117 | K8: =$K$5*$B$4^2 -> 153742.52 | L8: ='02 Raw Cost Data'!L13 -> 143516.31 | M8: =L8-K8 -> -10226.202 | N8: =$N$5*$B$4^2 -> 72743.702 | O8: ='02 Raw Cost Data'!M13 -> 73737.598 | P8: =O8-N8 -> 993.89605 | Q8: =$Q$5*$B$4^2 -> 88302.298 | R8: ='02 Raw Cost Data'!N13 -> 100098.44 | S8: =R8-Q8 -> 11796.137 | T8: =$T$5*$B$4^2 -> 75980.991 | U8: ='02 Raw Cost Data'!O13 -> 77229.281 | V8: =U8-T8 -> 1248.2897 | W8: =B8+E8+H8+K8+N8+Q8+T8 -> 705407.92 | X8: =C8+F8+I8+L8+O8+R8+U8 -> 720339.02 | Y8: =X8-W8 -> 14931.1 | Z8: =IF(W8=0,0,Y8/W8) -> 0.021166618 | AA8: =IF(Z8>0.05,"Unfavourable",IF(Z8<-0.05,"Favourable","On plan")) -> On plan
A9: 45901 | B9: =$B$5*$B$4^3 -> 162799.43 | C9: ='02 Raw Cost Data'!I14 -> 158979.41 | D9: =C9-B9 -> -3820.0155 | E9: =$E$5*$B$4^3 -> 89291.576 | F9: ='02 Raw Cost Data'!J14 -> 92261.506 | G9: =F9-E9 -> 2969.9297 | H9: =$H$5*$B$4^3 -> 66233.369 | I9: ='02 Raw Cost Data'!K14 -> 61211.517 | J9: =I9-H9 -> -5021.8513 | K9: =$K$5*$B$4^3 -> 155543.6 | L9: ='02 Raw Cost Data'!L14 -> 159667.6 | M9: =L9-K9 -> 4123.9979 | N9: =$N$5*$B$4^3 -> 73595.889 | O9: ='02 Raw Cost Data'!M14 -> 77160.957 | P9: =O9-N9 -> 3565.0684 | Q9: =$Q$5*$B$4^3 -> 89336.753 | R9: ='02 Raw Cost Data'!N14 -> 95928.862 | S9: =R9-Q9 -> 6592.1099 | T9: =$T$5*$B$4^3 -> 76871.102 | U9: ='02 Raw Cost Data'!O14 -> 81095.158 | V9: =U9-T9 -> 4224.056 | W9: =B9+E9+H9+K9+N9+Q9+T9 -> 713671.72 | X9: =C9+F9+I9+L9+O9+R9+U9 -> 726305.01 | Y9: =X9-W9 -> 12633.295 | Z9: =IF(W9=0,0,Y9/W9) -> 0.01770183 | AA9: =IF(Z9>0.05,"Unfavourable",IF(Z9<-0.05,"Favourable","On plan")) -> On plan
A10: 45931 | B10: =$B$5*$B$4^4 -> 164706.61 | C10: ='02 Raw Cost Data'!I15 -> 173558.54 | D10: =C10-B10 -> 8851.9301 | E10: =$E$5*$B$4^4 -> 90337.62 | F10: ='02 Raw Cost Data'!J15 -> 111068.97 | G10: =F10-E10 -> 20731.35 | H10: =$H$5*$B$4^4 -> 67009.287 | I10: ='02 Raw Cost Data'!K15 -> 61411.786 | J10: =I10-H10 -> -5597.5012 | K10: =$K$5*$B$4^4 -> 157365.78 | L10: ='02 Raw Cost Data'!L15 -> 164202.51 | M10: =L10-K10 -> 6836.7334 | N10: =$N$5*$B$4^4 -> 74458.058 | O10: ='02 Raw Cost Data'!M15 -> 87267.349 | P10: =O10-N10 -> 12809.291 | Q10: =$Q$5*$B$4^4 -> 90383.325 | R10: ='02 Raw Cost Data'!N15 -> 109009.59 | S10: =R10-Q10 -> 18626.262 | T10: =$T$5*$B$4^4 -> 77771.641 | U10: ='02 Raw Cost Data'!O15 -> 85190.819 | V10: =U10-T10 -> 7419.1784 | W10: =B10+E10+H10+K10+N10+Q10+T10 -> 722032.32 | X10: =C10+F10+I10+L10+O10+R10+U10 -> 791709.56 | Y10: =X10-W10 -> 69677.243 | Z10: =IF(W10=0,0,Y10/W10) -> 0.096501557 | AA10: =IF(Z10>0.05,"Unfavourable",IF(Z10<-0.05,"Favourable","On plan")) -> Unfavourable
A11: 45962 | B11: =$B$5*$B$4^5 -> 166636.14 | C11: ='02 Raw Cost Data'!I16 -> 170043.12 | D11: =C11-B11 -> 3406.9864 | E11: =$E$5*$B$4^5 -> 91395.918 | F11: ='02 Raw Cost Data'!J16 -> 132965.8 | G11: =F11-E11 -> 41569.88 | H11: =$H$5*$B$4^5 -> 67794.295 | I11: ='02 Raw Cost Data'!K16 -> 58841.39 | J11: =I11-H11 -> -8952.9053 | K11: =$K$5*$B$4^5 -> 159209.31 | L11: ='02 Raw Cost Data'!L16 -> 144469.26 | M11: =L11-K11 -> -14740.041 | N11: =$N$5*$B$4^5 -> 75330.328 | O11: ='02 Raw Cost Data'!M16 -> 85378.466 | P11: =O11-N11 -> 10048.138 | Q11: =$Q$5*$B$4^5 -> 91442.158 | R11: ='02 Raw Cost Data'!N16 -> 119213.62 | S11: =R11-Q11 -> 27771.465 | T11: =$T$5*$B$4^5 -> 78682.729 | U11: ='02 Raw Cost Data'!O16 -> 90806.45 | V11: =U11-T11 -> 12123.722 | W11: =B11+E11+H11+K11+N11+Q11+T11 -> 730490.87 | X11: =C11+F11+I11+L11+O11+R11+U11 -> 801718.11 | Y11: =X11-W11 -> 71227.245 | Z11: =IF(W11=0,0,Y11/W11) -> 0.097506002 | AA11: =IF(Z11>0.05,"Unfavourable",IF(Z11<-0.05,"Favourable","On plan")) -> Unfavourable
A12: 45992 | B12: =$B$5*$B$4^6 -> 168588.26 | C12: ='02 Raw Cost Data'!I17 -> 196719.21 | D12: =C12-B12 -> 28130.95 | E12: =$E$5*$B$4^6 -> 92466.613 | F12: ='02 Raw Cost Data'!J17 -> 126834.23 | G12: =F12-E12 -> 34367.621 | H12: =$H$5*$B$4^6 -> 68588.5 | I12: ='02 Raw Cost Data'!K17 -> 67374.564 | J12: =I12-H12 -> -1213.9352 | K12: =$K$5*$B$4^6 -> 161074.43 | L12: ='02 Raw Cost Data'!L17 -> 179764.62 | M12: =L12-K12 -> 18690.196 | N12: =$N$5*$B$4^6 -> 76212.817 | O12: ='02 Raw Cost Data'!M17 -> 77821.171 | P12: =O12-N12 -> 1608.3538 | Q12: =$Q$5*$B$4^6 -> 92513.396 | R12: ='02 Raw Cost Data'!N17 -> 113922.09 | S12: =R12-Q12 -> 21408.69 | T12: =$T$5*$B$4^6 -> 79604.491 | U12: ='02 Raw Cost Data'!O17 -> 93942.017 | V12: =U12-T12 -> 14337.526 | W12: =B12+E12+H12+K12+N12+Q12+T12 -> 739048.51 | X12: =C12+F12+I12+L12+O12+R12+U12 -> 856377.91 | Y12: =X12-W12 -> 117329.4 | Z12: =IF(W12=0,0,Y12/W12) -> 0.15875738 | AA12: =IF(Z12>0.05,"Unfavourable",IF(Z12<-0.05,"Favourable","On plan")) -> Unfavourable
A13: 46023 | B13: =$B$5*$B$4^7 -> 170563.26 | C13: ='02 Raw Cost Data'!I18 -> 198025.43 | D13: =C13-B13 -> 27462.173 | E13: =$E$5*$B$4^7 -> 93549.852 | F13: ='02 Raw Cost Data'!J18 -> 102962.32 | G13: =F13-E13 -> 9412.4702 | H13: =$H$5*$B$4^7 -> 69392.008 | I13: ='02 Raw Cost Data'!K18 -> 68852.693 | J13: =I13-H13 -> -539.31535 | K13: =$K$5*$B$4^7 -> 162961.4 | L13: ='02 Raw Cost Data'!L18 -> 181287.51 | M13: =L13-K13 -> 18326.103 | N13: =$N$5*$B$4^7 -> 77105.644 | O13: ='02 Raw Cost Data'!M18 -> 78034.495 | P13: =O13-N13 -> 928.85173 | Q13: =$Q$5*$B$4^7 -> 93597.182 | R13: ='02 Raw Cost Data'!N18 -> 92404.937 | S13: =R13-Q13 -> -1192.2449 | T13: =$T$5*$B$4^7 -> 80537.051 | U13: ='02 Raw Cost Data'!O18 -> 83037.662 | V13: =U13-T13 -> 2500.6114 | W13: =B13+E13+H13+K13+N13+Q13+T13 -> 747706.4 | X13: =C13+F13+I13+L13+O13+R13+U13 -> 804605.05 | Y13: =X13-W13 -> 56898.649 | Z13: =IF(W13=0,0,Y13/W13) -> 0.076097581 | AA13: =IF(Z13>0.05,"Unfavourable",IF(Z13<-0.05,"Favourable","On plan")) -> Unfavourable
A14: 46054 | B14: =$B$5*$B$4^8 -> 172561.4 | C14: ='02 Raw Cost Data'!I19 -> 172349.58 | D14: =C14-B14 -> -211.81291 | E14: =$E$5*$B$4^8 -> 94645.781 | F14: ='02 Raw Cost Data'!J19 -> 93784.657 | G14: =F14-E14 -> -861.12407 | H14: =$H$5*$B$4^8 -> 70204.93 | I14: ='02 Raw Cost Data'!K19 -> 64577.367 | J14: =I14-H14 -> -5627.5627 | K14: =$K$5*$B$4^8 -> 164870.48 | L14: ='02 Raw Cost Data'!L19 -> 145215.4 | M14: =L14-K14 -> -19655.079 | N14: =$N$5*$B$4^8 -> 78008.93 | O14: ='02 Raw Cost Data'!M19 -> 67682.038 | P14: =O14-N14 -> -10326.892 | Q14: =$Q$5*$B$4^8 -> 94693.666 | R14: ='02 Raw Cost Data'!N19 -> 87466.732 | S14: =R14-Q14 -> -7226.9337 | T14: =$T$5*$B$4^8 -> 81480.535 | U14: ='02 Raw Cost Data'!O19 -> 77358.65 | V14: =U14-T14 -> -4121.8859 | W14: =B14+E14+H14+K14+N14+Q14+T14 -> 756465.72 | X14: =C14+F14+I14+L14+O14+R14+U14 -> 708434.43 | Y14: =X14-W14 -> -48031.291 | Z14: =IF(W14=0,0,Y14/W14) -> -0.063494339 | AA14: =IF(Z14>0.05,"Unfavourable",IF(Z14<-0.05,"Favourable","On plan")) -> Favourable
A15: 46082 | B15: =$B$5*$B$4^9 -> 174582.94 | C15: ='02 Raw Cost Data'!I20 -> 207714.89 | D15: =C15-B15 -> 33131.953 | E15: =$E$5*$B$4^9 -> 95754.548 | F15: ='02 Raw Cost Data'!J20 -> 107075.45 | G15: =F15-E15 -> 11320.897 | H15: =$H$5*$B$4^9 -> 71027.375 | I15: ='02 Raw Cost Data'!K20 -> 74857.575 | J15: =I15-H15 -> 3830.2 | K15: =$K$5*$B$4^9 -> 166801.93 | L15: ='02 Raw Cost Data'!L20 -> 219042.95 | M15: =L15-K15 -> 52241.019 | N15: =$N$5*$B$4^9 -> 78922.798 | O15: ='02 Raw Cost Data'!M20 -> 74464.015 | P15: =O15-N15 -> -4458.7836 | Q15: =$Q$5*$B$4^9 -> 95802.994 | R15: ='02 Raw Cost Data'!N20 -> 100600.74 | S15: =R15-Q15 -> 4797.7467 | T15: =$T$5*$B$4^9 -> 82435.073 | U15: ='02 Raw Cost Data'!O20 -> 86338.602 | V15: =U15-T15 -> 3903.5288 | W15: =B15+E15+H15+K15+N15+Q15+T15 -> 765327.65 | X15: =C15+F15+I15+L15+O15+R15+U15 -> 870094.21 | Y15: =X15-W15 -> 104766.56 | Z15: =IF(W15=0,0,Y15/W15) -> 0.13689112 | AA15: =IF(Z15>0.05,"Unfavourable",IF(Z15<-0.05,"Favourable","On plan")) -> Unfavourable
A16: 46113 | B16: =$B$5*$B$4^10 -> 176628.16 | C16: ='02 Raw Cost Data'!I21 -> 215101.33 | D16: =C16-B16 -> 38473.171 | E16: =$E$5*$B$4^10 -> 96876.305 | F16: ='02 Raw Cost Data'!J21 -> 99504.595 | G16: =F16-E16 -> 2628.2907 | H16: =$H$5*$B$4^10 -> 71859.455 | I16: ='02 Raw Cost Data'!K21 -> 78120.424 | J16: =I16-H16 -> 6260.9693 | K16: =$K$5*$B$4^10 -> 168756 | L16: ='02 Raw Cost Data'!L21 -> 239549.44 | M16: =L16-K16 -> 70793.443 | N16: =$N$5*$B$4^10 -> 79847.372 | O16: ='02 Raw Cost Data'!M21 -> 72718.11 | P16: =O16-N16 -> -7129.2626 | Q16: =$Q$5*$B$4^10 -> 96925.318 | R16: ='02 Raw Cost Data'!N21 -> 94561.92 | S16: =R16-Q16 -> -2363.3978 | T16: =$T$5*$B$4^10 -> 83400.793 | U16: ='02 Raw Cost Data'!O21 -> 81252.916 | V16: =U16-T16 -> -2147.8776 | W16: =B16+E16+H16+K16+N16+Q16+T16 -> 774293.4 | X16: =C16+F16+I16+L16+O16+R16+U16 -> 880808.74 | Y16: =X16-W16 -> 106515.34 | Z16: =IF(W16=0,0,Y16/W16) -> 0.13756457 | AA16: =IF(Z16>0.05,"Unfavourable",IF(Z16<-0.05,"Favourable","On plan")) -> Unfavourable
A17: 46143 | B17: =$B$5*$B$4^11 -> 178697.35 | C17: ='02 Raw Cost Data'!I22 -> 199289.57 | D17: =C17-B17 -> 20592.227 | E17: =$E$5*$B$4^11 -> 98011.202 | F17: ='02 Raw Cost Data'!J22 -> 107902.82 | G17: =F17-E17 -> 9891.6134 | H17: =$H$5*$B$4^11 -> 72701.282 | I17: ='02 Raw Cost Data'!K22 -> 79901.899 | J17: =I17-H17 -> 7200.6167 | K17: =$K$5*$B$4^11 -> 170732.96 | L17: ='02 Raw Cost Data'!L22 -> 182830.56 | M17: =L17-K17 -> 12097.602 | N17: =$N$5*$B$4^11 -> 80782.777 | O17: ='02 Raw Cost Data'!M22 -> 77319.347 | P17: =O17-N17 -> -3463.4308 | Q17: =$Q$5*$B$4^11 -> 98060.79 | R17: ='02 Raw Cost Data'!N22 -> 102550.65 | S17: =R17-Q17 -> 4489.8596 | T17: =$T$5*$B$4^11 -> 84377.827 | U17: ='02 Raw Cost Data'!O22 -> 87225.165 | V17: =U17-T17 -> 2847.3382 | W17: =B17+E17+H17+K17+N17+Q17+T17 -> 783364.19 | X17: =C17+F17+I17+L17+O17+R17+U17 -> 837020.01 | Y17: =X17-W17 -> 53655.826 | Z17: =IF(W17=0,0,Y17/W17) -> 0.068494101 | AA17: =IF(Z17>0.05,"Unfavourable",IF(Z17<-0.05,"Favourable","On plan")) -> Unfavourable
A18: Total | B18: =SUM(B7:B17) -> 1855728.9 | C18: =SUM(C7:C17) -> 2013844.9 | D18: =SUM(D7:D17) -> 158115.97 | E18: =SUM(E7:E17) -> 1017822.7 | F18: =SUM(F7:F17) -> 1165465 | G18: =SUM(G7:G17) -> 147642.21 | H18: =SUM(H7:H17) -> 754985.32 | I18: =SUM(I7:I17) -> 750185.81 | ... Y18: =SUM(Y7:Y17) -> 585553.28 | Z18: =IF(W18=0,0,Y18/W18) -> 0.071979076
A20: Every business unit's bill rose over the period. Budget vs actual cannot tell you whether that is growth or waste -- the unit-economics layer in the repository does. This sheet shows the variance; the engine explains it.

Sheet 06 Forecast
A1: Forecast
A2: Twelve months forward. Trend = linear regression of each unit's monthly actuals on time (FORECAST). Run-rate = last three months' average grown at the active scenario's cloud growth. Two methods shown so the gap between them is visible.
A3: SIMULATED DATA. The estate is synthetic (FOCUS 1.2, 400 resources, 540 days). Figures illustrate the method; ground truth exists only because the data is simulated.
A6: Monthly growth factor (active scenario) | B6: =(1+'10 Assumptions'!$B$38)^(1/12) -> 1.0117149
A7: Last 3 months avg. total | B7: =AVERAGE('02 Raw Cost Data'!P20:P22) -> 862640.99
A8: Month | B8: bu-assist (trend) | C8: bu-checkout (trend) | D8: bu-datalake (trend) | E8: bu-datasci (trend) | F8: bu-platform (trend) | G8: bu-search (trend) | H8: unallocated (trend) | I8: Total (trend) | J8: Total (run-rate × growth) | K8: Gap
A9: 46174 | B9: =MAX(0,FORECAST(18,'02 Raw Cost Data'!$I$6:$I$22,'02 Raw Cost Data'!$H$6:$H$22)) -> 207745.85 | C9: =MAX(0,FORECAST(18,'02 Raw Cost Data'!$J$6:$J$22,'02 Raw Cost Data'!$H$6:$H$22)) -> 116352.86 | D9: =MAX(0,FORECAST(18,'02 Raw Cost Data'!$K$6:$K$22,'02 Raw Cost Data'!$H$6:$H$22)) -> 74573.172 | E9: =MAX(0,FORECAST(18,'02 Raw Cost Data'!$L$6:$L$22,'02 Raw Cost Data'!$H$6:$H$22)) -> 200417.06 | F9: =MAX(0,FORECAST(18,'02 Raw Cost Data'!$M$6:$M$22,'02 Raw Cost Data'!$H$6:$H$22)) -> 78415.899 | G9: =MAX(0,FORECAST(18,'02 Raw Cost Data'!$N$6:$N$22,'02 Raw Cost Data'!$H$6:$H$22)) -> 106842.68 | H9: =MAX(0,FORECAST(18,'02 Raw Cost Data'!$O$6:$O$22,'02 Raw Cost Data'!$H$6:$H$22)) -> 89642.279 | I9: =SUM(B9:H9) -> 873989.79 | J9: =$B$7*$B$6^1 -> 872746.76 | K9: =J9-I9 -> -1243.0392
A10: 46204 | B10: =MAX(0,FORECAST(19,'02 Raw Cost Data'!$I$6:$I$22,'02 Raw Cost Data'!$H$6:$H$22)) -> 211501.26 | C10: =MAX(0,FORECAST(19,'02 Raw Cost Data'!$J$6:$J$22,'02 Raw Cost Data'!$H$6:$H$22)) -> 118282.14 | D10: =MAX(0,FORECAST(19,'02 Raw Cost Data'!$K$6:$K$22,'02 Raw Cost Data'!$H$6:$H$22)) -> 75447.705 | E10: =MAX(0,FORECAST(19,'02 Raw Cost Data'!$L$6:$L$22,'02 Raw Cost Data'!$H$6:$H$22)) -> 204284.77 | F10: =MAX(0,FORECAST(19,'02 Raw Cost Data'!$M$6:$M$22,'02 Raw Cost Data'!$H$6:$H$22)) -> 78838.651 | G10: =MAX(0,FORECAST(19,'02 Raw Cost Data'!$N$6:$N$22,'02 Raw Cost Data'!$H$6:$H$22)) -> 108055.3 | H10: =MAX(0,FORECAST(19,'02 Raw Cost Data'!$O$6:$O$22,'02 Raw Cost Data'!$H$6:$H$22)) -> 90666.422 | I10: =SUM(B10:H10) -> 887076.25 | J10: =$B$7*$B$6^2 -> 882970.91 | K10: =J10-I10 -> -4105.3344
